{
  "prompt": "A calculator",
  "tasks": [
    {
      "task": "OpenAI API error: Error code: 404 - {'error': {'message': 'The model `gpt-4` does not exist or you do not have access to it.', 'type': 'invalid_request_error', 'param': None, 'code': 'model_not_found'}}",
      "code": "OpenAI API error: Error code: 404 - {'error': {'message': 'The model `gpt-4` does not exist or you do not have access to it.', 'type': 'invalid_request_error', 'param': None, 'code': 'model_not_found'}}",
      "qa_result": {
        "success": false,
        "error": "Traceback (most recent call last):\n  File \"/Users/josepeon/Documents/ZEROZERO/multi_agent_planner/agents/qa.py\", line 25, in evaluate_code\n    exec(code, {}, local_vars)\n  File \"<string>\", line 1\n    OpenAI API error: Error code: 404 - {'error': {'message': 'The model `gpt-4` does not exist or you do not have access to it.', 'type': 'invalid_request_error', 'param': None, 'code': 'model_not_found'}}\n           ^^^\nSyntaxError: invalid syntax\n",
        "output": null
      },
      "critique": "OpenAI API error: Error code: 404 - {'error': {'message': 'The model `gpt-4` does not exist or you do not have access to it.', 'type': 'invalid_request_error', 'param': None, 'code': 'model_not_found'}}",
      "attempts": 4
    }
  ]
}